2019-04-09 16:52:40,705 ERROR: Exception on /unfollow/user_88 [GET] [in /home/weiss/CODES/BM/intent_gatherer/intent_gatherer_venv/lib/python3.7/site-packages/flask/app.py:1761]
Traceback (most recent call last):
  File "/home/weiss/CODES/BM/intent_gatherer/intent_gatherer_venv/lib/python3.7/site-packages/sqlalchemy/orm/attributes.py", line 221, in __getattr__
    return getattr(self.comparator, key)
AttributeError: 'Comparator' object has no attribute 'filter_by'

During handling of the above exception, another exception occurred:

Traceback (most recent call last):
  File "/home/weiss/CODES/BM/intent_gatherer/intent_gatherer_venv/lib/python3.7/site-packages/flask/app.py", line 2292, in wsgi_app
    response = self.full_dispatch_request()
  File "/home/weiss/CODES/BM/intent_gatherer/intent_gatherer_venv/lib/python3.7/site-packages/flask/app.py", line 1815, in full_dispatch_request
    rv = self.handle_user_exception(e)
  File "/home/weiss/CODES/BM/intent_gatherer/intent_gatherer_venv/lib/python3.7/site-packages/flask/app.py", line 1718, in handle_user_exception
    reraise(exc_type, exc_value, tb)
  File "/home/weiss/CODES/BM/intent_gatherer/intent_gatherer_venv/lib/python3.7/site-packages/flask/_compat.py", line 35, in reraise
    raise value
  File "/home/weiss/CODES/BM/intent_gatherer/intent_gatherer_venv/lib/python3.7/site-packages/flask/app.py", line 1813, in full_dispatch_request
    rv = self.dispatch_request()
  File "/home/weiss/CODES/BM/intent_gatherer/intent_gatherer_venv/lib/python3.7/site-packages/flask/app.py", line 1799, in dispatch_request
    return self.view_functions[rule.endpoint](**req.view_args)
  File "/home/weiss/CODES/BM/intent_gatherer/intent_gatherer_venv/lib/python3.7/site-packages/flask_login/utils.py", line 261, in decorated_view
    return func(*args, **kwargs)
  File "/home/weiss/CODES/BM/intent_gatherer/flask_backend/app/routes.py", line 196, in unfollow
    user = User.followed.filter_by(username=username).first()
  File "/home/weiss/CODES/BM/intent_gatherer/intent_gatherer_venv/lib/python3.7/site-packages/sqlalchemy/orm/attributes.py", line 230, in __getattr__
    key,
AttributeError: Neither 'InstrumentedAttribute' object nor 'Comparator' object associated with User.followed has an attribute 'filter_by'
2019-04-09 16:52:40,712 ERROR: Internal error, please wait until the maintainers fix the issue [in /home/weiss/CODES/BM/intent_gatherer/flask_backend/app/errors.py:13]
2019-04-09 16:55:33,216 INFO: The application started [in /home/weiss/CODES/BM/intent_gatherer/flask_backend/app/__init__.py:44]
2019-04-09 16:55:37,003 ERROR: Exception on /unfollow/user_88 [GET] [in /home/weiss/CODES/BM/intent_gatherer/intent_gatherer_venv/lib/python3.7/site-packages/flask/app.py:1761]
Traceback (most recent call last):
  File "/home/weiss/CODES/BM/intent_gatherer/intent_gatherer_venv/lib/python3.7/site-packages/flask/app.py", line 2292, in wsgi_app
    response = self.full_dispatch_request()
  File "/home/weiss/CODES/BM/intent_gatherer/intent_gatherer_venv/lib/python3.7/site-packages/flask/app.py", line 1815, in full_dispatch_request
    rv = self.handle_user_exception(e)
  File "/home/weiss/CODES/BM/intent_gatherer/intent_gatherer_venv/lib/python3.7/site-packages/flask/app.py", line 1718, in handle_user_exception
    reraise(exc_type, exc_value, tb)
  File "/home/weiss/CODES/BM/intent_gatherer/intent_gatherer_venv/lib/python3.7/site-packages/flask/_compat.py", line 35, in reraise
    raise value
  File "/home/weiss/CODES/BM/intent_gatherer/intent_gatherer_venv/lib/python3.7/site-packages/flask/app.py", line 1813, in full_dispatch_request
    rv = self.dispatch_request()
  File "/home/weiss/CODES/BM/intent_gatherer/intent_gatherer_venv/lib/python3.7/site-packages/flask/app.py", line 1799, in dispatch_request
    return self.view_functions[rule.endpoint](**req.view_args)
  File "/home/weiss/CODES/BM/intent_gatherer/intent_gatherer_venv/lib/python3.7/site-packages/flask_login/utils.py", line 261, in decorated_view
    return func(*args, **kwargs)
  File "/home/weiss/CODES/BM/intent_gatherer/flask_backend/app/routes.py", line 204, in unfollow
    current_user.unofllow(user)
  File "/home/weiss/CODES/BM/intent_gatherer/intent_gatherer_venv/lib/python3.7/site-packages/werkzeug/local.py", line 348, in __getattr__
    return getattr(self._get_current_object(), name)
AttributeError: 'User' object has no attribute 'unofllow'
2019-04-09 16:55:37,028 ERROR: Internal error, please wait until the maintainers fix the issue [in /home/weiss/CODES/BM/intent_gatherer/flask_backend/app/errors.py:13]
2019-04-09 16:59:25,735 INFO: The application started [in /home/weiss/CODES/BM/intent_gatherer/flask_backend/app/__init__.py:44]
2019-04-09 17:00:09,662 ERROR: 404 not found [in /home/weiss/CODES/BM/intent_gatherer/flask_backend/app/errors.py:8]
2019-04-09 17:12:16,167 INFO: The application started [in /home/weiss/CODES/BM/intent_gatherer/flask_backend/app/__init__.py:44]
2019-04-09 17:13:17,041 INFO: The application started [in /home/weiss/CODES/BM/intent_gatherer/flask_backend/app/__init__.py:44]
2019-04-09 17:15:20,548 INFO: The application started [in /home/weiss/CODES/BM/intent_gatherer/flask_backend/app/__init__.py:44]
2019-04-09 17:15:47,166 INFO: The application started [in /home/weiss/CODES/BM/intent_gatherer/flask_backend/app/__init__.py:44]
2019-04-09 17:16:01,153 INFO: The application started [in /home/weiss/CODES/BM/intent_gatherer/flask_backend/app/__init__.py:44]
2019-04-09 17:22:55,517 INFO: The application started [in /home/weiss/CODES/BM/intent_gatherer/flask_backend/app/__init__.py:44]
2019-04-09 17:23:53,263 INFO: The application started [in /home/weiss/CODES/BM/intent_gatherer/flask_backend/app/__init__.py:44]
2019-04-09 17:24:12,341 ERROR: 404 not found [in /home/weiss/CODES/BM/intent_gatherer/flask_backend/app/errors.py:8]
2019-04-11 16:11:49,488 INFO: The application started [in /home/weiss/CODES/PFE_M2/asr/dataset_gatherer/transribe/app/__init__.py:22]
2019-04-11 16:11:59,404 INFO: The application started [in /home/weiss/CODES/PFE_M2/asr/dataset_gatherer/transribe/app/__init__.py:22]
2019-04-11 16:12:08,536 INFO: The application started [in /home/weiss/CODES/PFE_M2/asr/dataset_gatherer/transribe/app/__init__.py:22]
2019-04-11 16:12:34,229 INFO: The application started [in /home/weiss/CODES/PFE_M2/asr/dataset_gatherer/transribe/app/__init__.py:22]
2019-04-11 16:12:39,048 ERROR: 404 not found [in /home/weiss/CODES/PFE_M2/asr/dataset_gatherer/transribe/app/errors.py:8]
2019-04-11 16:13:46,833 INFO: The application started [in /home/weiss/CODES/PFE_M2/asr/dataset_gatherer/transribe/app/__init__.py:22]
2019-04-11 16:15:20,552 INFO: The application started [in /home/weiss/CODES/PFE_M2/asr/dataset_gatherer/transribe/app/__init__.py:22]
2019-04-11 16:15:48,388 INFO: The application started [in /home/weiss/CODES/PFE_M2/asr/dataset_gatherer/transribe/app/__init__.py:22]
2019-04-11 16:16:13,398 INFO: The application started [in /home/weiss/CODES/PFE_M2/asr/dataset_gatherer/transribe/app/__init__.py:22]
2019-04-11 16:17:45,539 INFO: The application started [in /home/weiss/CODES/PFE_M2/asr/dataset_gatherer/transribe/app/__init__.py:22]
2019-04-11 16:19:11,785 INFO: The application started [in /home/weiss/CODES/PFE_M2/asr/dataset_gatherer/transribe/app/__init__.py:22]
2019-04-11 16:19:56,030 INFO: The application started [in /home/weiss/CODES/PFE_M2/asr/dataset_gatherer/transribe/app/__init__.py:22]
2019-04-11 16:20:19,726 INFO: The application started [in /home/weiss/CODES/PFE_M2/asr/dataset_gatherer/transribe/app/__init__.py:22]
2019-04-11 16:20:29,153 INFO: The application started [in /home/weiss/CODES/PFE_M2/asr/dataset_gatherer/transribe/app/__init__.py:22]
2019-04-11 16:20:46,234 INFO: The application started [in /home/weiss/CODES/PFE_M2/asr/dataset_gatherer/transribe/app/__init__.py:22]
2019-04-11 16:21:06,323 INFO: The application started [in /home/weiss/CODES/PFE_M2/asr/dataset_gatherer/transribe/app/__init__.py:22]
2019-04-11 16:21:22,994 INFO: The application started [in /home/weiss/CODES/PFE_M2/asr/dataset_gatherer/transribe/app/__init__.py:22]
2019-04-11 16:21:44,937 INFO: The application started [in /home/weiss/CODES/PFE_M2/asr/dataset_gatherer/transribe/app/__init__.py:22]
2019-04-11 16:21:59,130 INFO: The application started [in /home/weiss/CODES/PFE_M2/asr/dataset_gatherer/transribe/app/__init__.py:22]
2019-04-11 16:22:17,851 INFO: The application started [in /home/weiss/CODES/PFE_M2/asr/dataset_gatherer/transribe/app/__init__.py:22]
2019-04-11 16:22:30,648 INFO: The application started [in /home/weiss/CODES/PFE_M2/asr/dataset_gatherer/transribe/app/__init__.py:22]
2019-04-11 16:23:23,229 INFO: The application started [in /home/weiss/CODES/PFE_M2/asr/dataset_gatherer/transribe/app/__init__.py:22]
2019-04-11 16:23:58,099 INFO: The application started [in /home/weiss/CODES/PFE_M2/asr/dataset_gatherer/transribe/app/__init__.py:22]
2019-04-11 16:24:34,413 INFO: The application started [in /home/weiss/CODES/PFE_M2/asr/dataset_gatherer/transribe/app/__init__.py:22]
2019-04-11 16:24:55,961 INFO: The application started [in /home/weiss/CODES/PFE_M2/asr/dataset_gatherer/transribe/app/__init__.py:22]
2019-04-11 16:25:20,460 INFO: The application started [in /home/weiss/CODES/PFE_M2/asr/dataset_gatherer/transribe/app/__init__.py:22]
2019-04-11 16:25:54,541 INFO: The application started [in /home/weiss/CODES/PFE_M2/asr/dataset_gatherer/transribe/app/__init__.py:22]
2019-04-11 16:30:26,824 INFO: The application started [in /home/weiss/CODES/PFE_M2/asr/dataset_gatherer/transribe/app/__init__.py:22]
2019-04-11 16:30:50,682 INFO: The application started [in /home/weiss/CODES/PFE_M2/asr/dataset_gatherer/transribe/app/__init__.py:22]
2019-04-11 16:32:02,551 INFO: The application started [in /home/weiss/CODES/PFE_M2/asr/dataset_gatherer/transribe/app/__init__.py:22]
2019-04-11 16:32:45,816 INFO: The application started [in /home/weiss/CODES/PFE_M2/asr/dataset_gatherer/transribe/app/__init__.py:22]
2019-04-11 16:36:55,705 INFO: The application started [in /home/weiss/CODES/PFE_M2/asr/dataset_gatherer/transribe/app/__init__.py:22]
2019-04-11 16:37:30,657 INFO: The application started [in /home/weiss/CODES/PFE_M2/asr/dataset_gatherer/transribe/app/__init__.py:22]
2019-04-11 16:37:53,943 INFO: The application started [in /home/weiss/CODES/PFE_M2/asr/dataset_gatherer/transribe/app/__init__.py:22]
2019-04-11 16:42:14,322 INFO: The application started [in /home/weiss/CODES/PFE_M2/asr/dataset_gatherer/transribe/app/__init__.py:22]
2019-04-11 16:43:26,443 INFO: The application started [in /home/weiss/CODES/PFE_M2/asr/dataset_gatherer/transribe/app/__init__.py:22]
2019-04-11 16:43:46,064 INFO: The application started [in /home/weiss/CODES/PFE_M2/asr/dataset_gatherer/transribe/app/__init__.py:22]
2019-04-11 16:44:10,431 INFO: The application started [in /home/weiss/CODES/PFE_M2/asr/dataset_gatherer/transribe/app/__init__.py:22]
2019-04-11 16:44:24,989 INFO: The application started [in /home/weiss/CODES/PFE_M2/asr/dataset_gatherer/transribe/app/__init__.py:22]
2019-04-11 16:45:15,978 INFO: The application started [in /home/weiss/CODES/PFE_M2/asr/dataset_gatherer/transribe/app/__init__.py:22]
2019-04-11 17:02:51,136 INFO: The application started [in /home/weiss/CODES/PFE_M2/asr/dataset_gatherer/transribe/app/__init__.py:22]
2019-04-11 17:02:59,287 ERROR: 404 not found [in /home/weiss/CODES/PFE_M2/asr/dataset_gatherer/transribe/app/errors.py:8]
2019-04-11 17:04:23,943 INFO: The application started [in /home/weiss/CODES/PFE_M2/asr/dataset_gatherer/transribe/app/__init__.py:22]
2019-04-11 17:04:44,962 INFO: The application started [in /home/weiss/CODES/PFE_M2/asr/dataset_gatherer/transribe/app/__init__.py:22]
2019-04-11 17:05:24,325 INFO: The application started [in /home/weiss/CODES/PFE_M2/asr/dataset_gatherer/transribe/app/__init__.py:22]
2019-04-11 17:05:49,227 INFO: The application started [in /home/weiss/CODES/PFE_M2/asr/dataset_gatherer/transribe/app/__init__.py:22]
2019-04-11 17:08:43,806 INFO: The application started [in /home/weiss/CODES/PFE_M2/asr/dataset_gatherer/transribe/app/__init__.py:22]
2019-04-11 17:10:27,629 INFO: The application started [in /home/weiss/CODES/PFE_M2/asr/dataset_gatherer/transribe/app/__init__.py:22]
2019-04-11 17:28:30,121 INFO: The application started [in /home/weiss/CODES/PFE_M2/asr/dataset_gatherer/transribe/app/__init__.py:22]
2019-04-11 17:28:34,906 INFO: The application started [in /home/weiss/CODES/PFE_M2/asr/dataset_gatherer/transribe/app/__init__.py:22]
2019-04-11 17:29:06,229 INFO: The application started [in /home/weiss/CODES/PFE_M2/asr/dataset_gatherer/transribe/app/__init__.py:22]
2019-04-11 17:29:13,495 INFO: The application started [in /home/weiss/CODES/PFE_M2/asr/dataset_gatherer/transribe/app/__init__.py:22]
2019-04-11 17:29:23,377 INFO: The application started [in /home/weiss/CODES/PFE_M2/asr/dataset_gatherer/transribe/app/__init__.py:22]
2019-04-11 17:29:26,161 INFO: The application started [in /home/weiss/CODES/PFE_M2/asr/dataset_gatherer/transribe/app/__init__.py:22]
2019-04-11 17:29:31,099 INFO: The application started [in /home/weiss/CODES/PFE_M2/asr/dataset_gatherer/transribe/app/__init__.py:22]
2019-04-11 17:29:35,691 INFO: The application started [in /home/weiss/CODES/PFE_M2/asr/dataset_gatherer/transribe/app/__init__.py:22]
2019-04-11 17:29:37,821 INFO: The application started [in /home/weiss/CODES/PFE_M2/asr/dataset_gatherer/transribe/app/__init__.py:22]
2019-04-11 17:33:32,896 INFO: The application started [in /home/weiss/CODES/PFE_M2/asr/dataset_gatherer/transribe/app/__init__.py:22]
2019-04-11 17:33:46,427 ERROR: Exception on / [GET] [in /home/weiss/Tools/python3-virtenv/weiss@Quantum-venv/lib/python3.6/site-packages/flask/app.py:1761]
Traceback (most recent call last):
  File "/home/weiss/Tools/python3-virtenv/weiss@Quantum-venv/lib/python3.6/site-packages/flask/app.py", line 2292, in wsgi_app
    response = self.full_dispatch_request()
  File "/home/weiss/Tools/python3-virtenv/weiss@Quantum-venv/lib/python3.6/site-packages/flask/app.py", line 1815, in full_dispatch_request
    rv = self.handle_user_exception(e)
  File "/home/weiss/Tools/python3-virtenv/weiss@Quantum-venv/lib/python3.6/site-packages/flask/app.py", line 1718, in handle_user_exception
    reraise(exc_type, exc_value, tb)
  File "/home/weiss/Tools/python3-virtenv/weiss@Quantum-venv/lib/python3.6/site-packages/flask/_compat.py", line 35, in reraise
    raise value
  File "/home/weiss/Tools/python3-virtenv/weiss@Quantum-venv/lib/python3.6/site-packages/flask/app.py", line 1813, in full_dispatch_request
    rv = self.dispatch_request()
  File "/home/weiss/Tools/python3-virtenv/weiss@Quantum-venv/lib/python3.6/site-packages/flask/app.py", line 1799, in dispatch_request
    return self.view_functions[rule.endpoint](**req.view_args)
  File "/home/weiss/CODES/PFE_M2/asr/dataset_gatherer/transribe/app/routes.py", line 21, in index
    init()
  File "/home/weiss/CODES/PFE_M2/asr/dataset_gatherer/transribe/app/routes.py", line 35, in init
    emit('recieve', {'Utterance':all[random_index]})
  File "/home/weiss/Tools/python3-virtenv/weiss@Quantum-venv/lib/python3.6/site-packages/flask_socketio/__init__.py", line 714, in emit
    namespace = flask.request.namespace
  File "/home/weiss/Tools/python3-virtenv/weiss@Quantum-venv/lib/python3.6/site-packages/werkzeug/local.py", line 348, in __getattr__
    return getattr(self._get_current_object(), name)
AttributeError: 'Request' object has no attribute 'namespace'
2019-04-11 17:33:46,484 ERROR: Internal error, please wait until the maintainers fix the issue [in /home/weiss/CODES/PFE_M2/asr/dataset_gatherer/transribe/app/errors.py:13]
2019-04-11 17:36:34,170 INFO: The application started [in /home/weiss/CODES/PFE_M2/asr/dataset_gatherer/transribe/app/__init__.py:22]
2019-04-11 17:36:38,362 ERROR: Exception on / [GET] [in /home/weiss/Tools/python3-virtenv/weiss@Quantum-venv/lib/python3.6/site-packages/flask/app.py:1761]
Traceback (most recent call last):
  File "/home/weiss/Tools/python3-virtenv/weiss@Quantum-venv/lib/python3.6/site-packages/flask/app.py", line 2292, in wsgi_app
    response = self.full_dispatch_request()
  File "/home/weiss/Tools/python3-virtenv/weiss@Quantum-venv/lib/python3.6/site-packages/flask/app.py", line 1815, in full_dispatch_request
    rv = self.handle_user_exception(e)
  File "/home/weiss/Tools/python3-virtenv/weiss@Quantum-venv/lib/python3.6/site-packages/flask/app.py", line 1718, in handle_user_exception
    reraise(exc_type, exc_value, tb)
  File "/home/weiss/Tools/python3-virtenv/weiss@Quantum-venv/lib/python3.6/site-packages/flask/_compat.py", line 35, in reraise
    raise value
  File "/home/weiss/Tools/python3-virtenv/weiss@Quantum-venv/lib/python3.6/site-packages/flask/app.py", line 1813, in full_dispatch_request
    rv = self.dispatch_request()
  File "/home/weiss/Tools/python3-virtenv/weiss@Quantum-venv/lib/python3.6/site-packages/flask/app.py", line 1799, in dispatch_request
    return self.view_functions[rule.endpoint](**req.view_args)
  File "/home/weiss/CODES/PFE_M2/asr/dataset_gatherer/transribe/app/routes.py", line 21, in index
    init()
  File "/home/weiss/CODES/PFE_M2/asr/dataset_gatherer/transribe/app/routes.py", line 35, in init
    emit('recieve', {'Utterance':all[random_index]})
  File "/home/weiss/Tools/python3-virtenv/weiss@Quantum-venv/lib/python3.6/site-packages/flask_socketio/__init__.py", line 714, in emit
    namespace = flask.request.namespace
  File "/home/weiss/Tools/python3-virtenv/weiss@Quantum-venv/lib/python3.6/site-packages/werkzeug/local.py", line 348, in __getattr__
    return getattr(self._get_current_object(), name)
AttributeError: 'Request' object has no attribute 'namespace'
2019-04-11 17:36:38,364 ERROR: Internal error, please wait until the maintainers fix the issue [in /home/weiss/CODES/PFE_M2/asr/dataset_gatherer/transribe/app/errors.py:13]
2019-04-11 17:36:57,026 INFO: The application started [in /home/weiss/CODES/PFE_M2/asr/dataset_gatherer/transribe/app/__init__.py:22]
2019-04-11 17:36:58,406 ERROR: Exception on / [GET] [in /home/weiss/Tools/python3-virtenv/weiss@Quantum-venv/lib/python3.6/site-packages/flask/app.py:1761]
Traceback (most recent call last):
  File "/home/weiss/Tools/python3-virtenv/weiss@Quantum-venv/lib/python3.6/site-packages/flask/app.py", line 2292, in wsgi_app
    response = self.full_dispatch_request()
  File "/home/weiss/Tools/python3-virtenv/weiss@Quantum-venv/lib/python3.6/site-packages/flask/app.py", line 1815, in full_dispatch_request
    rv = self.handle_user_exception(e)
  File "/home/weiss/Tools/python3-virtenv/weiss@Quantum-venv/lib/python3.6/site-packages/flask/app.py", line 1718, in handle_user_exception
    reraise(exc_type, exc_value, tb)
  File "/home/weiss/Tools/python3-virtenv/weiss@Quantum-venv/lib/python3.6/site-packages/flask/_compat.py", line 35, in reraise
    raise value
  File "/home/weiss/Tools/python3-virtenv/weiss@Quantum-venv/lib/python3.6/site-packages/flask/app.py", line 1813, in full_dispatch_request
    rv = self.dispatch_request()
  File "/home/weiss/Tools/python3-virtenv/weiss@Quantum-venv/lib/python3.6/site-packages/flask/app.py", line 1799, in dispatch_request
    return self.view_functions[rule.endpoint](**req.view_args)
  File "/home/weiss/CODES/PFE_M2/asr/dataset_gatherer/transribe/app/routes.py", line 21, in index
    init()
  File "/home/weiss/CODES/PFE_M2/asr/dataset_gatherer/transribe/app/routes.py", line 36, in init
    emit('recieve', {'Utterance':all[random_index]})
  File "/home/weiss/Tools/python3-virtenv/weiss@Quantum-venv/lib/python3.6/site-packages/flask_socketio/__init__.py", line 714, in emit
    namespace = flask.request.namespace
  File "/home/weiss/Tools/python3-virtenv/weiss@Quantum-venv/lib/python3.6/site-packages/werkzeug/local.py", line 348, in __getattr__
    return getattr(self._get_current_object(), name)
AttributeError: 'Request' object has no attribute 'namespace'
2019-04-11 17:36:58,408 ERROR: Internal error, please wait until the maintainers fix the issue [in /home/weiss/CODES/PFE_M2/asr/dataset_gatherer/transribe/app/errors.py:13]
2019-04-11 17:38:44,376 INFO: The application started [in /home/weiss/CODES/PFE_M2/asr/dataset_gatherer/transribe/app/__init__.py:22]
2019-04-11 17:41:12,875 INFO: The application started [in /home/weiss/CODES/PFE_M2/asr/dataset_gatherer/transribe/app/__init__.py:22]
