2019-04-09 11:52:55,666 INFO: The application started [in /home/weiss/CODES/BM/intent_gatherer/flask_backend/app/__init__.py:44]
2019-04-09 11:59:01,038 INFO: The application started [in /home/weiss/CODES/BM/intent_gatherer/flask_backend/app/__init__.py:44]
2019-04-09 12:03:09,813 INFO: The application started [in /home/weiss/CODES/BM/intent_gatherer/flask_backend/app/__init__.py:44]
2019-04-09 12:04:00,282 INFO: The application started [in /home/weiss/CODES/BM/intent_gatherer/flask_backend/app/__init__.py:44]
2019-04-09 12:07:49,980 INFO: The application started [in /home/weiss/CODES/BM/intent_gatherer/flask_backend/app/__init__.py:44]
2019-04-09 12:08:35,861 INFO: The application started [in /home/weiss/CODES/BM/intent_gatherer/flask_backend/app/__init__.py:44]
2019-04-09 12:35:45,995 INFO: The application started [in /home/weiss/CODES/BM/intent_gatherer/flask_backend/app/__init__.py:44]
2019-04-09 12:36:19,782 INFO: The application started [in /home/weiss/CODES/BM/intent_gatherer/flask_backend/app/__init__.py:44]
2019-04-09 12:37:36,318 INFO: The application started [in /home/weiss/CODES/BM/intent_gatherer/flask_backend/app/__init__.py:44]
2019-04-09 12:38:04,753 INFO: The application started [in /home/weiss/CODES/BM/intent_gatherer/flask_backend/app/__init__.py:44]
2019-04-09 12:38:30,703 INFO: The application started [in /home/weiss/CODES/BM/intent_gatherer/flask_backend/app/__init__.py:44]
2019-04-09 12:39:30,295 INFO: The application started [in /home/weiss/CODES/BM/intent_gatherer/flask_backend/app/__init__.py:44]
2019-04-09 12:40:07,225 INFO: The application started [in /home/weiss/CODES/BM/intent_gatherer/flask_backend/app/__init__.py:44]
2019-04-09 12:55:03,642 INFO: The application started [in /home/weiss/CODES/BM/intent_gatherer/flask_backend/app/__init__.py:44]
2019-04-09 12:55:43,498 INFO: The application started [in /home/weiss/CODES/BM/intent_gatherer/flask_backend/app/__init__.py:44]
2019-04-09 12:57:23,111 INFO: The application started [in /home/weiss/CODES/BM/intent_gatherer/flask_backend/app/__init__.py:44]
2019-04-09 12:57:56,077 INFO: The application started [in /home/weiss/CODES/BM/intent_gatherer/flask_backend/app/__init__.py:44]
2019-04-09 12:58:38,136 INFO: The application started [in /home/weiss/CODES/BM/intent_gatherer/flask_backend/app/__init__.py:44]
2019-04-09 12:58:52,161 INFO: The application started [in /home/weiss/CODES/BM/intent_gatherer/flask_backend/app/__init__.py:44]
2019-04-09 13:30:41,910 INFO: The application started [in /home/weiss/CODES/BM/intent_gatherer/flask_backend/app/__init__.py:44]
2019-04-09 13:31:23,063 ERROR: Exception on /index [GET] [in /home/weiss/CODES/BM/intent_gatherer/intent_gatherer_venv/lib/python3.7/site-packages/flask/app.py:1761]
Traceback (most recent call last):
  File "/home/weiss/CODES/BM/intent_gatherer/intent_gatherer_venv/lib/python3.7/site-packages/flask/app.py", line 2292, in wsgi_app
    response = self.full_dispatch_request()
  File "/home/weiss/CODES/BM/intent_gatherer/intent_gatherer_venv/lib/python3.7/site-packages/flask/app.py", line 1815, in full_dispatch_request
    rv = self.handle_user_exception(e)
  File "/home/weiss/CODES/BM/intent_gatherer/intent_gatherer_venv/lib/python3.7/site-packages/flask/app.py", line 1718, in handle_user_exception
    reraise(exc_type, exc_value, tb)
  File "/home/weiss/CODES/BM/intent_gatherer/intent_gatherer_venv/lib/python3.7/site-packages/flask/_compat.py", line 35, in reraise
    raise value
  File "/home/weiss/CODES/BM/intent_gatherer/intent_gatherer_venv/lib/python3.7/site-packages/flask/app.py", line 1813, in full_dispatch_request
    rv = self.dispatch_request()
  File "/home/weiss/CODES/BM/intent_gatherer/intent_gatherer_venv/lib/python3.7/site-packages/flask/app.py", line 1799, in dispatch_request
    return self.view_functions[rule.endpoint](**req.view_args)
  File "/home/weiss/CODES/BM/intent_gatherer/intent_gatherer_venv/lib/python3.7/site-packages/flask_login/utils.py", line 261, in decorated_view
    return func(*args, **kwargs)
  File "/home/weiss/CODES/BM/intent_gatherer/flask_backend/app/routes.py", line 28, in index
    return render_template('index.html')
  File "/home/weiss/CODES/BM/intent_gatherer/intent_gatherer_venv/lib/python3.7/site-packages/flask/templating.py", line 135, in render_template
    context, ctx.app)
  File "/home/weiss/CODES/BM/intent_gatherer/intent_gatherer_venv/lib/python3.7/site-packages/flask/templating.py", line 117, in _render
    rv = template.render(context)
  File "/home/weiss/CODES/BM/intent_gatherer/intent_gatherer_venv/lib/python3.7/site-packages/jinja2/asyncsupport.py", line 76, in render
    return original_render(self, *args, **kwargs)
  File "/home/weiss/CODES/BM/intent_gatherer/intent_gatherer_venv/lib/python3.7/site-packages/jinja2/environment.py", line 1008, in render
    return self.environment.handle_exception(exc_info, True)
  File "/home/weiss/CODES/BM/intent_gatherer/intent_gatherer_venv/lib/python3.7/site-packages/jinja2/environment.py", line 780, in handle_exception
    reraise(exc_type, exc_value, tb)
  File "/home/weiss/CODES/BM/intent_gatherer/intent_gatherer_venv/lib/python3.7/site-packages/jinja2/_compat.py", line 37, in reraise
    raise value.with_traceback(tb)
  File "/home/weiss/CODES/BM/intent_gatherer/flask_backend/app/templates/index.html", line 1, in top-level template code
    {% extends 'base.html' %}
  File "/home/weiss/CODES/BM/intent_gatherer/flask_backend/app/templates/base.html", line 34, in top-level template code
    {% endwith %}{% block content %}{% endblock %}
  File "/home/weiss/CODES/BM/intent_gatherer/flask_backend/app/templates/index.html", line 5, in block "content"
    {{ form.hidden_tag }}
  File "/home/weiss/CODES/BM/intent_gatherer/intent_gatherer_venv/lib/python3.7/site-packages/jinja2/environment.py", line 430, in getattr
    return getattr(obj, attribute)
jinja2.exceptions.UndefinedError: 'form' is undefined
2019-04-09 13:31:23,108 ERROR: Internal error, please wait until the maintainers fix the issue [in /home/weiss/CODES/BM/intent_gatherer/flask_backend/app/errors.py:13]
2019-04-09 13:37:10,953 INFO: The application started [in /home/weiss/CODES/BM/intent_gatherer/flask_backend/app/__init__.py:44]
2019-04-09 14:00:15,956 INFO: The application started [in /home/weiss/CODES/BM/intent_gatherer/flask_backend/app/__init__.py:44]
2019-04-09 14:00:43,689 INFO: The application started [in /home/weiss/CODES/BM/intent_gatherer/flask_backend/app/__init__.py:44]
2019-04-09 14:00:48,421 ERROR: Exception on /index [POST] [in /home/weiss/CODES/BM/intent_gatherer/intent_gatherer_venv/lib/python3.7/site-packages/flask/app.py:1761]
Traceback (most recent call last):
  File "/home/weiss/CODES/BM/intent_gatherer/intent_gatherer_venv/lib/python3.7/site-packages/sqlalchemy/engine/base.py", line 1244, in _execute_context
    cursor, statement, parameters, context
  File "/home/weiss/CODES/BM/intent_gatherer/intent_gatherer_venv/lib/python3.7/site-packages/sqlalchemy/engine/default.py", line 552, in do_execute
    cursor.execute(statement, parameters)
sqlite3.InterfaceError: Error binding parameter 2 - probably unsupported type.

The above exception was the direct cause of the following exception:

Traceback (most recent call last):
  File "/home/weiss/CODES/BM/intent_gatherer/intent_gatherer_venv/lib/python3.7/site-packages/flask/app.py", line 2292, in wsgi_app
    response = self.full_dispatch_request()
  File "/home/weiss/CODES/BM/intent_gatherer/intent_gatherer_venv/lib/python3.7/site-packages/flask/app.py", line 1815, in full_dispatch_request
    rv = self.handle_user_exception(e)
  File "/home/weiss/CODES/BM/intent_gatherer/intent_gatherer_venv/lib/python3.7/site-packages/flask/app.py", line 1718, in handle_user_exception
    reraise(exc_type, exc_value, tb)
  File "/home/weiss/CODES/BM/intent_gatherer/intent_gatherer_venv/lib/python3.7/site-packages/flask/_compat.py", line 35, in reraise
    raise value
  File "/home/weiss/CODES/BM/intent_gatherer/intent_gatherer_venv/lib/python3.7/site-packages/flask/app.py", line 1813, in full_dispatch_request
    rv = self.dispatch_request()
  File "/home/weiss/CODES/BM/intent_gatherer/intent_gatherer_venv/lib/python3.7/site-packages/flask/app.py", line 1799, in dispatch_request
    return self.view_functions[rule.endpoint](**req.view_args)
  File "/home/weiss/CODES/BM/intent_gatherer/intent_gatherer_venv/lib/python3.7/site-packages/flask_login/utils.py", line 261, in decorated_view
    return func(*args, **kwargs)
  File "/home/weiss/CODES/BM/intent_gatherer/flask_backend/app/routes.py", line 32, in index
    db.session.commit()
  File "/home/weiss/CODES/BM/intent_gatherer/intent_gatherer_venv/lib/python3.7/site-packages/sqlalchemy/orm/scoping.py", line 162, in do
    return getattr(self.registry(), name)(*args, **kwargs)
  File "/home/weiss/CODES/BM/intent_gatherer/intent_gatherer_venv/lib/python3.7/site-packages/sqlalchemy/orm/session.py", line 1026, in commit
    self.transaction.commit()
  File "/home/weiss/CODES/BM/intent_gatherer/intent_gatherer_venv/lib/python3.7/site-packages/sqlalchemy/orm/session.py", line 493, in commit
    self._prepare_impl()
  File "/home/weiss/CODES/BM/intent_gatherer/intent_gatherer_venv/lib/python3.7/site-packages/sqlalchemy/orm/session.py", line 472, in _prepare_impl
    self.session.flush()
  File "/home/weiss/CODES/BM/intent_gatherer/intent_gatherer_venv/lib/python3.7/site-packages/sqlalchemy/orm/session.py", line 2451, in flush
    self._flush(objects)
  File "/home/weiss/CODES/BM/intent_gatherer/intent_gatherer_venv/lib/python3.7/site-packages/sqlalchemy/orm/session.py", line 2589, in _flush
    transaction.rollback(_capture_exception=True)
  File "/home/weiss/CODES/BM/intent_gatherer/intent_gatherer_venv/lib/python3.7/site-packages/sqlalchemy/util/langhelpers.py", line 68, in __exit__
    compat.reraise(exc_type, exc_value, exc_tb)
  File "/home/weiss/CODES/BM/intent_gatherer/intent_gatherer_venv/lib/python3.7/site-packages/sqlalchemy/util/compat.py", line 129, in reraise
    raise value
  File "/home/weiss/CODES/BM/intent_gatherer/intent_gatherer_venv/lib/python3.7/site-packages/sqlalchemy/orm/session.py", line 2549, in _flush
    flush_context.execute()
  File "/home/weiss/CODES/BM/intent_gatherer/intent_gatherer_venv/lib/python3.7/site-packages/sqlalchemy/orm/unitofwork.py", line 422, in execute
    rec.execute(self)
  File "/home/weiss/CODES/BM/intent_gatherer/intent_gatherer_venv/lib/python3.7/site-packages/sqlalchemy/orm/unitofwork.py", line 589, in execute
    uow,
  File "/home/weiss/CODES/BM/intent_gatherer/intent_gatherer_venv/lib/python3.7/site-packages/sqlalchemy/orm/persistence.py", line 245, in save_obj
    insert,
  File "/home/weiss/CODES/BM/intent_gatherer/intent_gatherer_venv/lib/python3.7/site-packages/sqlalchemy/orm/persistence.py", line 1120, in _emit_insert_statements
    statement, params
  File "/home/weiss/CODES/BM/intent_gatherer/intent_gatherer_venv/lib/python3.7/site-packages/sqlalchemy/engine/base.py", line 988, in execute
    return meth(self, multiparams, params)
  File "/home/weiss/CODES/BM/intent_gatherer/intent_gatherer_venv/lib/python3.7/site-packages/sqlalchemy/sql/elements.py", line 287, in _execute_on_connection
    return connection._execute_clauseelement(self, multiparams, params)
  File "/home/weiss/CODES/BM/intent_gatherer/intent_gatherer_venv/lib/python3.7/site-packages/sqlalchemy/engine/base.py", line 1107, in _execute_clauseelement
    distilled_params,
  File "/home/weiss/CODES/BM/intent_gatherer/intent_gatherer_venv/lib/python3.7/site-packages/sqlalchemy/engine/base.py", line 1248, in _execute_context
    e, statement, parameters, cursor, context
  File "/home/weiss/CODES/BM/intent_gatherer/intent_gatherer_venv/lib/python3.7/site-packages/sqlalchemy/engine/base.py", line 1466, in _handle_dbapi_exception
    util.raise_from_cause(sqlalchemy_exception, exc_info)
  File "/home/weiss/CODES/BM/intent_gatherer/intent_gatherer_venv/lib/python3.7/site-packages/sqlalchemy/util/compat.py", line 383, in raise_from_cause
    reraise(type(exception), exception, tb=exc_tb, cause=cause)
  File "/home/weiss/CODES/BM/intent_gatherer/intent_gatherer_venv/lib/python3.7/site-packages/sqlalchemy/util/compat.py", line 128, in reraise
    raise value.with_traceback(tb)
  File "/home/weiss/CODES/BM/intent_gatherer/intent_gatherer_venv/lib/python3.7/site-packages/sqlalchemy/engine/base.py", line 1244, in _execute_context
    cursor, statement, parameters, context
  File "/home/weiss/CODES/BM/intent_gatherer/intent_gatherer_venv/lib/python3.7/site-packages/sqlalchemy/engine/default.py", line 552, in do_execute
    cursor.execute(statement, parameters)
sqlalchemy.exc.InterfaceError: <unprintable InterfaceError object>
2019-04-09 14:00:48,464 ERROR: Internal error, please wait until the maintainers fix the issue [in /home/weiss/CODES/BM/intent_gatherer/flask_backend/app/errors.py:13]
2019-04-09 14:03:41,623 INFO: The application started [in /home/weiss/CODES/BM/intent_gatherer/flask_backend/app/__init__.py:44]
2019-04-09 14:03:51,353 ERROR: Exception on / [POST] [in /home/weiss/CODES/BM/intent_gatherer/intent_gatherer_venv/lib/python3.7/site-packages/flask/app.py:1761]
Traceback (most recent call last):
  File "/home/weiss/CODES/BM/intent_gatherer/intent_gatherer_venv/lib/python3.7/site-packages/sqlalchemy/engine/base.py", line 1244, in _execute_context
    cursor, statement, parameters, context
  File "/home/weiss/CODES/BM/intent_gatherer/intent_gatherer_venv/lib/python3.7/site-packages/sqlalchemy/engine/default.py", line 552, in do_execute
    cursor.execute(statement, parameters)
sqlite3.InterfaceError: Error binding parameter 2 - probably unsupported type.

The above exception was the direct cause of the following exception:

Traceback (most recent call last):
  File "/home/weiss/CODES/BM/intent_gatherer/intent_gatherer_venv/lib/python3.7/site-packages/flask/app.py", line 2292, in wsgi_app
    response = self.full_dispatch_request()
  File "/home/weiss/CODES/BM/intent_gatherer/intent_gatherer_venv/lib/python3.7/site-packages/flask/app.py", line 1815, in full_dispatch_request
    rv = self.handle_user_exception(e)
  File "/home/weiss/CODES/BM/intent_gatherer/intent_gatherer_venv/lib/python3.7/site-packages/flask/app.py", line 1718, in handle_user_exception
    reraise(exc_type, exc_value, tb)
  File "/home/weiss/CODES/BM/intent_gatherer/intent_gatherer_venv/lib/python3.7/site-packages/flask/_compat.py", line 35, in reraise
    raise value
  File "/home/weiss/CODES/BM/intent_gatherer/intent_gatherer_venv/lib/python3.7/site-packages/flask/app.py", line 1813, in full_dispatch_request
    rv = self.dispatch_request()
  File "/home/weiss/CODES/BM/intent_gatherer/intent_gatherer_venv/lib/python3.7/site-packages/flask/app.py", line 1799, in dispatch_request
    return self.view_functions[rule.endpoint](**req.view_args)
  File "/home/weiss/CODES/BM/intent_gatherer/intent_gatherer_venv/lib/python3.7/site-packages/flask_login/utils.py", line 261, in decorated_view
    return func(*args, **kwargs)
  File "/home/weiss/CODES/BM/intent_gatherer/flask_backend/app/routes.py", line 32, in index
    db.session.commit()
  File "/home/weiss/CODES/BM/intent_gatherer/intent_gatherer_venv/lib/python3.7/site-packages/sqlalchemy/orm/scoping.py", line 162, in do
    return getattr(self.registry(), name)(*args, **kwargs)
  File "/home/weiss/CODES/BM/intent_gatherer/intent_gatherer_venv/lib/python3.7/site-packages/sqlalchemy/orm/session.py", line 1026, in commit
    self.transaction.commit()
  File "/home/weiss/CODES/BM/intent_gatherer/intent_gatherer_venv/lib/python3.7/site-packages/sqlalchemy/orm/session.py", line 493, in commit
    self._prepare_impl()
  File "/home/weiss/CODES/BM/intent_gatherer/intent_gatherer_venv/lib/python3.7/site-packages/sqlalchemy/orm/session.py", line 472, in _prepare_impl
    self.session.flush()
  File "/home/weiss/CODES/BM/intent_gatherer/intent_gatherer_venv/lib/python3.7/site-packages/sqlalchemy/orm/session.py", line 2451, in flush
    self._flush(objects)
  File "/home/weiss/CODES/BM/intent_gatherer/intent_gatherer_venv/lib/python3.7/site-packages/sqlalchemy/orm/session.py", line 2589, in _flush
    transaction.rollback(_capture_exception=True)
  File "/home/weiss/CODES/BM/intent_gatherer/intent_gatherer_venv/lib/python3.7/site-packages/sqlalchemy/util/langhelpers.py", line 68, in __exit__
    compat.reraise(exc_type, exc_value, exc_tb)
  File "/home/weiss/CODES/BM/intent_gatherer/intent_gatherer_venv/lib/python3.7/site-packages/sqlalchemy/util/compat.py", line 129, in reraise
    raise value
  File "/home/weiss/CODES/BM/intent_gatherer/intent_gatherer_venv/lib/python3.7/site-packages/sqlalchemy/orm/session.py", line 2549, in _flush
    flush_context.execute()
  File "/home/weiss/CODES/BM/intent_gatherer/intent_gatherer_venv/lib/python3.7/site-packages/sqlalchemy/orm/unitofwork.py", line 422, in execute
    rec.execute(self)
  File "/home/weiss/CODES/BM/intent_gatherer/intent_gatherer_venv/lib/python3.7/site-packages/sqlalchemy/orm/unitofwork.py", line 589, in execute
    uow,
  File "/home/weiss/CODES/BM/intent_gatherer/intent_gatherer_venv/lib/python3.7/site-packages/sqlalchemy/orm/persistence.py", line 245, in save_obj
    insert,
  File "/home/weiss/CODES/BM/intent_gatherer/intent_gatherer_venv/lib/python3.7/site-packages/sqlalchemy/orm/persistence.py", line 1120, in _emit_insert_statements
    statement, params
  File "/home/weiss/CODES/BM/intent_gatherer/intent_gatherer_venv/lib/python3.7/site-packages/sqlalchemy/engine/base.py", line 988, in execute
    return meth(self, multiparams, params)
  File "/home/weiss/CODES/BM/intent_gatherer/intent_gatherer_venv/lib/python3.7/site-packages/sqlalchemy/sql/elements.py", line 287, in _execute_on_connection
    return connection._execute_clauseelement(self, multiparams, params)
  File "/home/weiss/CODES/BM/intent_gatherer/intent_gatherer_venv/lib/python3.7/site-packages/sqlalchemy/engine/base.py", line 1107, in _execute_clauseelement
    distilled_params,
  File "/home/weiss/CODES/BM/intent_gatherer/intent_gatherer_venv/lib/python3.7/site-packages/sqlalchemy/engine/base.py", line 1248, in _execute_context
    e, statement, parameters, cursor, context
  File "/home/weiss/CODES/BM/intent_gatherer/intent_gatherer_venv/lib/python3.7/site-packages/sqlalchemy/engine/base.py", line 1466, in _handle_dbapi_exception
    util.raise_from_cause(sqlalchemy_exception, exc_info)
  File "/home/weiss/CODES/BM/intent_gatherer/intent_gatherer_venv/lib/python3.7/site-packages/sqlalchemy/util/compat.py", line 383, in raise_from_cause
    reraise(type(exception), exception, tb=exc_tb, cause=cause)
  File "/home/weiss/CODES/BM/intent_gatherer/intent_gatherer_venv/lib/python3.7/site-packages/sqlalchemy/util/compat.py", line 128, in reraise
    raise value.with_traceback(tb)
  File "/home/weiss/CODES/BM/intent_gatherer/intent_gatherer_venv/lib/python3.7/site-packages/sqlalchemy/engine/base.py", line 1244, in _execute_context
    cursor, statement, parameters, context
  File "/home/weiss/CODES/BM/intent_gatherer/intent_gatherer_venv/lib/python3.7/site-packages/sqlalchemy/engine/default.py", line 552, in do_execute
    cursor.execute(statement, parameters)
sqlalchemy.exc.InterfaceError: <unprintable InterfaceError object>
2019-04-09 14:03:51,404 ERROR: Internal error, please wait until the maintainers fix the issue [in /home/weiss/CODES/BM/intent_gatherer/flask_backend/app/errors.py:13]
2019-04-09 14:24:34,689 INFO: The application started [in /home/weiss/CODES/BM/intent_gatherer/flask_backend/app/__init__.py:44]
2019-04-09 14:29:04,468 INFO: The application started [in /home/weiss/CODES/BM/intent_gatherer/flask_backend/app/__init__.py:44]
